<?xml version="1.0"?>
<robot name="cylinder_pivot" 
  xmlns:xacro="http://www.ros.org/wiki/xacro">

  <material name="red">
    <color rgba="0.6 0 0 1" />
  </material>

  <xacro:include filename="$(find ackrm_robot)/urdf/inertia.xacro" />

  <xacro:macro name="cylinder_pivot" params="name pr ph pm xpos ypos">
    <link name="${name}_steer_pivot">
      <visual>
        <geometry>
          <cylinder length="${ph}" radius="${pr}" />
        </geometry>
        <origin rpy="0 0 0" xyz="0 0 0" />
        <material name="red" />
      </visual>
      <!-- <collision>
        <geometry>
          <cylinder length="${ph}" radius="${pr}" />
        </geometry>
        <origin rpy="0 0 0" xyz="0 0 0" />
      </collision> -->
      <inertial>
        <mass value="${pm}" />
        <origin rpy="0 0 0" xyz="0 0 0" />
        <xacro:cylinder_inertia m="${pm}" r="${pr}" h="${ph}" />
      </inertial>
    </link>

    <joint name="${name}_steer_joint" type="revolute">
      <parent link="base_link" />
      <child link="${name}_steer_pivot" />
      <origin xyz="${xpos} ${ypos} 0" rpy="0 0 0" />
      <axis xyz="0 0 1" rpy="0  0" />
      <limit lower="${-pi/4}" upper="${pi/4}" effort="1000" velocity="100" />
      <joint_properties damping="0.0" friction="100.0" />
    </joint>

    <transmission name="${name}_pivot_trans">
      <type>transmission_interface/SimpleTransmission</type>
      <joint name="${name}_steer_joint">
        <hardwareInterface>hardware_interface/PositionJointInterface</hardwareInterface>
      </joint>
      <actuator name="${name}_steer_motor">
        <mechanicalReduction>1</mechanicalReduction>
      </actuator>
    </transmission>

    <gazebo reference="${name}_steer_pivot">
      <mu1 value="1.0" />
      <mu2 value="1.0" />
      <fdir1 value="0 0 1" />
      <kp value="10000000.0" />
      <kd value="1.0" />
      <material>Gazebo/Red</material>
      <turnGravityOff>false</turnGravityOff>
    </gazebo>
  </xacro:macro>

</robot>