<?xml version="1.0"?>
<robot name="cylinder_wheel" 
  xmlns:xacro="http://www.ros.org/wiki/xacro">

  <material name="blue">
    <color rgba="0.164 0.321 0.745 1" />
  </material>

  <xacro:include filename="$(find ackrm_robot)/urdf/inertia.xacro" />

  <xacro:macro name="cylinder_wheel" params="name wr wh wm parent xpos ypos">
    <link name="${name}_wheel">
      <visual>
        <geometry>
          <cylinder length="${wh}" radius="${wr}" />
        </geometry>
        <origin rpy="1.57 0 0" xyz="0 0 0" />
        <material name="blue" />
      </visual>
      <collision>
        <geometry>
          <cylinder length="${wh}" radius="${wr}" />
        </geometry>
        <origin rpy="1.57 0 0" xyz="0 0 0" />
      </collision>
      <inertial>
        <mass value="${wm}" />
        <origin rpy="1.57 0 0" xyz="0 0 0" />
        <xacro:cylinder_inertia m="${wm}" r="${wr}" h="${wh}" />
      </inertial>
    </link>

    <joint name="${name}_wheel_joint" type="continuous">
      <parent link="${parent}" />
      <child link="${name}_wheel" />
      <origin xyz="${xpos} ${ypos} 0" rpy="0 0 0" />
      <axis xyz="0 1 0" rpy="0  0" />
      <limit effort="1000" velocity="100" />
      <joint_properties damping="0.0" friction="10.0" />
    </joint>

    <transmission name="${name}_wheel_trans">
      <type>transmission_interface/SimpleTransmission</type>
      <joint name="${name}_wheel_joint">
        <hardwareInterface>hardware_interface/VelocityJointInterface</hardwareInterface>
      </joint>
      <actuator name="${name}_wheel_motor">
        <mechanicalReduction>1</mechanicalReduction>
      </actuator>
    </transmission>

    <gazebo reference="${name}_wheel">
      <mu1 value="200.0" />
      <mu2 value="100.0" />
      <fdir1 value="1 0 0" />
      <kp value="10000000.0" />
      <kd value="1.0" />
      <material>Gazebo/Blue</material>
      <turnGravityOff>false</turnGravityOff>
    </gazebo>
  </xacro:macro>

</robot>